Workbook

Sheet Monthly Summary (Airtel)
B2: Individuals
C3: OPT-Ins | D3: Mandatory Svgs | E3: DISBURSEMENTS | I3: REPAYMENTS | L3: PERFORMANCE
B4: ID_MNTH | C4: CUST_BASE | D4: TXN_VAL | E4: TXN_VOL | F4: TXN_VAL | G4: CUST_COUNT | H4: AV_TICKET_SIZE | I4: TXN_VOL | J4: TXN_VAL | K4: CUST_COUNT | L4: DUE | M4: OUTSTANDING
B5: Nov-2022 | C5: 153848 | D5: =5%*F5 -> 952293.3 | E5: =SUMIFS('Daily Summary(Airtel)'!$F$4:$F$1048576,'Daily Summary(Airtel)'!$B$4:$B$1048576,B5) -> 38515 | F5: =SUMIFS('Daily Summary(Airtel)'!$G$4:$G$1048576,'Daily Summary(Airtel)'!$B$4:$B$1048576,B5) -> 19045866 | G5: =SUMIFS('Daily Summary(Airtel)'!$H$4:$H$1048576,'Daily Summary(Airtel)'!$B$4:$B$1048576,B5) -> 38448 | H5: =F5/E5 -> 494.50515 | I5: =SUMIFS('Daily Summary(Airtel)'!$M$4:$M$1048576,'Daily Summary(Airtel)'!$B$4:$B$1048576,B5) -> 17260 | J5: =SUMIFS('Daily Summary(Airtel)'!$N$4:$N$1048576,'Daily Summary(Airtel)'!$B$4:$B$1048576,B5) -> 5020962.3 | K5: =SUMIFS('Daily Summary(Airtel)'!$O$4:$O$1048576,'Daily Summary(Airtel)'!$B$4:$B$1048576,B5) -> 15673 | L5: 18578138 | M5: 18578142 | N5: 18578142 | O5: 18578138
B6: Dec-2022 | C6: 721186 | D6: =5%*F6 -> 18822490 | E6: =SUMIFS('Daily Summary(Airtel)'!$F$4:$F$1048576,'Daily Summary(Airtel)'!$B$4:$B$1048576,B6) -> 762072 | F6: =SUMIFS('Daily Summary(Airtel)'!$G$4:$G$1048576,'Daily Summary(Airtel)'!$B$4:$B$1048576,B6) -> 376449796 | G6: =SUMIFS('Daily Summary(Airtel)'!$H$4:$H$1048576,'Daily Summary(Airtel)'!$B$4:$B$1048576,B6) -> 759911 | H6: =F6/E6 -> 493.98193 | I6: =SUMIFS('Daily Summary(Airtel)'!$M$4:$M$1048576,'Daily Summary(Airtel)'!$B$4:$B$1048576,B6) -> 268241 | J6: =SUMIFS('Daily Summary(Airtel)'!$N$4:$N$1048576,'Daily Summary(Airtel)'!$B$4:$B$1048576,B6) -> 81456028 | K6: =SUMIFS('Daily Summary(Airtel)'!$O$4:$O$1048576,'Daily Summary(Airtel)'!$B$4:$B$1048576,B6) -> 245749 | L6: 3.8985988e+08 | M6: 3.898599e+08 | N6: 3.898599e+08 | O6: 3.8985988e+08
B7: Jan-2023 | C7: 44987 | D7: =5%*F7 -> 2644865.2 | E7: =SUMIFS('Daily Summary(Airtel)'!$F$4:$F$1048576,'Daily Summary(Airtel)'!$B$4:$B$1048576,B7) -> 107644 | F7: =SUMIFS('Daily Summary(Airtel)'!$G$4:$G$1048576,'Daily Summary(Airtel)'!$B$4:$B$1048576,B7) -> 52897303 | G7: =SUMIFS('Daily Summary(Airtel)'!$H$4:$H$1048576,'Daily Summary(Airtel)'!$B$4:$B$1048576,B7) -> 107438 | H7: =F7/E7 -> 491.40967 | I7: =SUMIFS('Daily Summary(Airtel)'!$M$4:$M$1048576,'Daily Summary(Airtel)'!$B$4:$B$1048576,B7) -> 51124 | J7: =SUMIFS('Daily Summary(Airtel)'!$N$4:$N$1048576,'Daily Summary(Airtel)'!$B$4:$B$1048576,B7) -> 17393999 | K7: =SUMIFS('Daily Summary(Airtel)'!$O$4:$O$1048576,'Daily Summary(Airtel)'!$B$4:$B$1048576,B7) -> 47674 | L7: 46792239 | M7: 46792241 | N7: 46792241 | O7: 46792239
B8: Feb-2023 | C8: 23726 | D8: =5%*F8 -> 1943505.9 | E8: =SUMIFS('Daily Summary(Airtel)'!$F$4:$F$1048576,'Daily Summary(Airtel)'!$B$4:$B$1048576,B8) -> 71763 | F8: =SUMIFS('Daily Summary(Airtel)'!$G$4:$G$1048576,'Daily Summary(Airtel)'!$B$4:$B$1048576,B8) -> 38870118 | G8: =SUMIFS('Daily Summary(Airtel)'!$H$4:$H$1048576,'Daily Summary(Airtel)'!$B$4:$B$1048576,B8) -> 71520 | H8: =F8/E8 -> 541.64567 | I8: =SUMIFS('Daily Summary(Airtel)'!$M$4:$M$1048576,'Daily Summary(Airtel)'!$B$4:$B$1048576,B8) -> 44598 | J8: =SUMIFS('Daily Summary(Airtel)'!$N$4:$N$1048576,'Daily Summary(Airtel)'!$B$4:$B$1048576,B8) -> 17501745 | K8: =SUMIFS('Daily Summary(Airtel)'!$O$4:$O$1048576,'Daily Summary(Airtel)'!$B$4:$B$1048576,B8) -> 41261 | L8: 28160119 | M8: 28160120 | N8: 28160120 | O8: 28160119
B9: Mar-2023 | C9: 33271 | D9: =5%*F9 -> 1774143.2 | E9: =SUMIFS('Daily Summary(Airtel)'!$F$4:$F$1048576,'Daily Summary(Airtel)'!$B$4:$B$1048576,B9) -> 65487 | F9: =SUMIFS('Daily Summary(Airtel)'!$G$4:$G$1048576,'Daily Summary(Airtel)'!$B$4:$B$1048576,B9) -> 35482865 | G9: =SUMIFS('Daily Summary(Airtel)'!$H$4:$H$1048576,'Daily Summary(Airtel)'!$B$4:$B$1048576,B9) -> 65245 | H9: =F9/E9 -> 541.83067 | I9: =SUMIFS('Daily Summary(Airtel)'!$M$4:$M$1048576,'Daily Summary(Airtel)'!$B$4:$B$1048576,B9) -> 36489 | J9: =SUMIFS('Daily Summary(Airtel)'!$N$4:$N$1048576,'Daily Summary(Airtel)'!$B$4:$B$1048576,B9) -> 13913926 | K9: =SUMIFS('Daily Summary(Airtel)'!$O$4:$O$1048576,'Daily Summary(Airtel)'!$B$4:$B$1048576,B9) -> 33294 | L9: 28442370 | M9: 28442370 | N9: 28442370 | O9: 28442370
B10: Apr-2023 | C10: 23946 | D10: =5%*F10 -> 1113322.6 | E10: =SUMIFS('Daily Summary(Airtel)'!$F$4:$F$1048576,'Daily Summary(Airtel)'!$B$4:$B$1048576,B10) -> 41507 | F10: =SUMIFS('Daily Summary(Airtel)'!$G$4:$G$1048576,'Daily Summary(Airtel)'!$B$4:$B$1048576,B10) -> 22266452 | G10: =SUMIFS('Daily Summary(Airtel)'!$H$4:$H$1048576,'Daily Summary(Airtel)'!$B$4:$B$1048576,B10) -> 41400 | H10: =F10/E10 -> 536.45053 | I10: =SUMIFS('Daily Summary(Airtel)'!$M$4:$M$1048576,'Daily Summary(Airtel)'!$B$4:$B$1048576,B10) -> 22499 | J10: =SUMIFS('Daily Summary(Airtel)'!$N$4:$N$1048576,'Daily Summary(Airtel)'!$B$4:$B$1048576,B10) -> 8484917.7 | K10: =SUMIFS('Daily Summary(Airtel)'!$O$4:$O$1048576,'Daily Summary(Airtel)'!$B$4:$B$1048576,B10) -> 20355 | L10: 18004262 | M10: 18004262 | N10: 18004262 | O10: 18004262
B11: May-2023 | C11: 20781 | D11: =5%*F11 -> 893555.15 | E11: =SUMIFS('Daily Summary(Airtel)'!$F$4:$F$1048576,'Daily Summary(Airtel)'!$B$4:$B$1048576,B11) -> 33393 | F11: =SUMIFS('Daily Summary(Airtel)'!$G$4:$G$1048576,'Daily Summary(Airtel)'!$B$4:$B$1048576,B11) -> 17871103 | G11: =SUMIFS('Daily Summary(Airtel)'!$H$4:$H$1048576,'Daily Summary(Airtel)'!$B$4:$B$1048576,B11) -> 33311 | H11: =F11/E11 -> 535.17513 | I11: =SUMIFS('Daily Summary(Airtel)'!$M$4:$M$1048576,'Daily Summary(Airtel)'!$B$4:$B$1048576,B11) -> 17374 | J11: =SUMIFS('Daily Summary(Airtel)'!$N$4:$N$1048576,'Daily Summary(Airtel)'!$B$4:$B$1048576,B11) -> 6607478.6 | K11: =SUMIFS('Daily Summary(Airtel)'!$O$4:$O$1048576,'Daily Summary(Airtel)'!$B$4:$B$1048576,B11) -> 15952 | L11: 14579894 | M11: 14579894 | N11: 14579894 | O11: 14579894
B12: Jun-2023 | C12: 17479 | D12: =5%*F12 -> 757464.9 | E12: =SUMIFS('Daily Summary(Airtel)'!$F$4:$F$1048576,'Daily Summary(Airtel)'!$B$4:$B$1048576,B12) -> 28314 | F12: =SUMIFS('Daily Summary(Airtel)'!$G$4:$G$1048576,'Daily Summary(Airtel)'!$B$4:$B$1048576,B12) -> 15149298 | G12: =SUMIFS('Daily Summary(Airtel)'!$H$4:$H$1048576,'Daily Summary(Airtel)'!$B$4:$B$1048576,B12) -> 28251 | H12: =F12/E12 -> 535.0462 | I12: =SUMIFS('Daily Summary(Airtel)'!$M$4:$M$1048576,'Daily Summary(Airtel)'!$B$4:$B$1048576,B12) -> 15245 | J12: =SUMIFS('Daily Summary(Airtel)'!$N$4:$N$1048576,'Daily Summary(Airtel)'!$B$4:$B$1048576,B12) -> 5661462.6 | K12: =SUMIFS('Daily Summary(Airtel)'!$O$4:$O$1048576,'Daily Summary(Airtel)'!$B$4:$B$1048576,B12) -> 13971 | L12: 12200835 | M12: 12200835 | N12: 12200835 | O12: 12200835
B13: Jul-2023 | C13: 13709 | D13: =5%*F13 -> 591678.8 | E13: =SUMIFS('Daily Summary(Airtel)'!$F$4:$F$1048576,'Daily Summary(Airtel)'!$B$4:$B$1048576,B13) -> 22035 | F13: =SUMIFS('Daily Summary(Airtel)'!$G$4:$G$1048576,'Daily Summary(Airtel)'!$B$4:$B$1048576,B13) -> 11833576 | G13: =SUMIFS('Daily Summary(Airtel)'!$H$4:$H$1048576,'Daily Summary(Airtel)'!$B$4:$B$1048576,B13) -> 21990 | H13: =F13/E13 -> 537.03544 | I13: =SUMIFS('Daily Summary(Airtel)'!$M$4:$M$1048576,'Daily Summary(Airtel)'!$B$4:$B$1048576,B13) -> 12304 | J13: =SUMIFS('Daily Summary(Airtel)'!$N$4:$N$1048576,'Daily Summary(Airtel)'!$B$4:$B$1048576,B13) -> 4593175.2 | K13: =SUMIFS('Daily Summary(Airtel)'!$O$4:$O$1048576,'Daily Summary(Airtel)'!$B$4:$B$1048576,B13) -> 11258 | L13: 9264341.8 | M13: 9264342.6 | N13: 9264342.6 | O13: 9264341.8
B14: Aug-2023 | C14: 10850 | D14: =5%*F14 -> 375436.6 | E14: =SUMIFS('Daily Summary(Airtel)'!$F$4:$F$1048576,'Daily Summary(Airtel)'!$B$4:$B$1048576,B14) -> 13870 | F14: =SUMIFS('Daily Summary(Airtel)'!$G$4:$G$1048576,'Daily Summary(Airtel)'!$B$4:$B$1048576,B14) -> 7508732 | G14: =SUMIFS('Daily Summary(Airtel)'!$H$4:$H$1048576,'Daily Summary(Airtel)'!$B$4:$B$1048576,B14) -> 13841 | H14: =F14/E14 -> 541.36496 | I14: =SUMIFS('Daily Summary(Airtel)'!$M$4:$M$1048576,'Daily Summary(Airtel)'!$B$4:$B$1048576,B14) -> 10095 | J14: =SUMIFS('Daily Summary(Airtel)'!$N$4:$N$1048576,'Daily Summary(Airtel)'!$B$4:$B$1048576,B14) -> 3384159.4 | K14: =SUMIFS('Daily Summary(Airtel)'!$O$4:$O$1048576,'Daily Summary(Airtel)'!$B$4:$B$1048576,B14) -> 9085 | L14: 5306763.1 | M14: 5306763.1 | N14: 5306763.1 | O14: 5306763.1
B15: Sept-2023 | C15: 5728 | D15: =5%*F15 -> 143199.9 | E15: =SUMIFS('Daily Summary(Airtel)'!$F$4:$F$1048576,'Daily Summary(Airtel)'!$B$4:$B$1048576,B15) -> 5013 | F15: =SUMIFS('Daily Summary(Airtel)'!$G$4:$G$1048576,'Daily Summary(Airtel)'!$B$4:$B$1048576,B15) -> 2863998 | G15: =SUMIFS('Daily Summary(Airtel)'!$H$4:$H$1048576,'Daily Summary(Airtel)'!$B$4:$B$1048576,B15) -> 5005 | H15: =F15/E15 -> 571.31418 | I15: =SUMIFS('Daily Summary(Airtel)'!$M$4:$M$1048576,'Daily Summary(Airtel)'!$B$4:$B$1048576,B15) -> 5926 | J15: =SUMIFS('Daily Summary(Airtel)'!$N$4:$N$1048576,'Daily Summary(Airtel)'!$B$4:$B$1048576,B15) -> 2003586.2 | K15: =SUMIFS('Daily Summary(Airtel)'!$O$4:$O$1048576,'Daily Summary(Airtel)'!$B$4:$B$1048576,B15) -> 5254 | L15: 1207852.7 | M15: 1207852.7 | N15: 1207852.7 | O15: 1207852.7
B16: Oct-2023 | C16: 3536 | D16: =5%*F16 -> 62580.7 | E16: =SUMIFS('Daily Summary(Airtel)'!$F$4:$F$1048576,'Daily Summary(Airtel)'!$B$4:$B$1048576,B16) -> 2374 | F16: =SUMIFS('Daily Summary(Airtel)'!$G$4:$G$1048576,'Daily Summary(Airtel)'!$B$4:$B$1048576,B16) -> 1251614 | G16: =SUMIFS('Daily Summary(Airtel)'!$H$4:$H$1048576,'Daily Summary(Airtel)'!$B$4:$B$1048576,B16) -> 2371 | H16: =F16/E16 -> 527.21735 | I16: =SUMIFS('Daily Summary(Airtel)'!$M$4:$M$1048576,'Daily Summary(Airtel)'!$B$4:$B$1048576,B16) -> 2207 | J16: =SUMIFS('Daily Summary(Airtel)'!$N$4:$N$1048576,'Daily Summary(Airtel)'!$B$4:$B$1048576,B16) -> 684796.44 | K16: =SUMIFS('Daily Summary(Airtel)'!$O$4:$O$1048576,'Daily Summary(Airtel)'!$B$4:$B$1048576,B16) -> 1955 | L16: 774630.99 | M16: 774630.99 | N16: 774630.99 | O16: 774630.99
... B23: May-2024 | C23: 2901 | D23: =5%*F23 -> 54358 | E23: =SUMIFS('Daily Summary(Airtel)'!$F$4:$F$1048576,'Daily Summary(Airtel)'!$B$4:$B$1048576,B23) -> 1801 | F23: =SUMIFS('Daily Summary(Airtel)'!$G$4:$G$1048576,'Daily Summary(Airtel)'!$B$4:$B$1048576,B23) -> 1087160 | G23: =SUMIFS('Daily Summary(Airtel)'!$H$4:$H$1048576,'Daily Summary(Airtel)'!$B$4:$B$1048576,B23) -> 1789 | H23: =F23/E23 -> 603.64242 | I23: =SUMIFS('Daily Summary(Airtel)'!$M$4:$M$1048576,'Daily Summary(Airtel)'!$B$4:$B$1048576,B23) -> 1579 | J23: =SUMIFS('Daily Summary(Airtel)'!$N$4:$N$1048576,'Daily Summary(Airtel)'!$B$4:$B$1048576,B23) -> 610712.56 | K23: =SUMIFS('Daily Summary(Airtel)'!$O$4:$O$1048576,'Daily Summary(Airtel)'!$B$4:$B$1048576,B23) -> 1436 | L23: 568636.29 | M23: 568636.29 | N23: 568636.29 | O23: 568636.29
B24: Jun-2024 | C24: 2811 | D24: =5%*F24 -> 0 | E24: =SUMIFS('Daily Summary(Airtel)'!$F$4:$F$1048576,'Daily Summary(Airtel)'!$B$4:$B$1048576,B24) -> 0 | F24: =SUMIFS('Daily Summary(Airtel)'!$G$4:$G$1048576,'Daily Summary(Airtel)'!$B$4:$B$1048576,B24) -> 0 | G24: =SUMIFS('Daily Summary(Airtel)'!$H$4:$H$1048576,'Daily Summary(Airtel)'!$B$4:$B$1048576,B24) -> 0 | I24: =SUMIFS('Daily Summary(Airtel)'!$M$4:$M$1048576,'Daily Summary(Airtel)'!$B$4:$B$1048576,B24) -> 0 | J24: =SUMIFS('Daily Summary(Airtel)'!$N$4:$N$1048576,'Daily Summary(Airtel)'!$B$4:$B$1048576,B24) -> 0 | K24: =SUMIFS('Daily Summary(Airtel)'!$O$4:$O$1048576,'Daily Summary(Airtel)'!$B$4:$B$1048576,B24) -> 0
B25: Jul-2024 | C25: 2676 | D25: =5%*F25 -> 97935.6 | E25: =SUMIFS('Daily Summary(Airtel)'!$F$4:$F$1048576,'Daily Summary(Airtel)'!$B$4:$B$1048576,B25) -> 3628 | F25: =SUMIFS('Daily Summary(Airtel)'!$G$4:$G$1048576,'Daily Summary(Airtel)'!$B$4:$B$1048576,B25) -> 1958712 | G25: =SUMIFS('Daily Summary(Airtel)'!$H$4:$H$1048576,'Daily Summary(Airtel)'!$B$4:$B$1048576,B25) -> 3609 | H25: =F25/E25 -> 539.88754 | I25: =SUMIFS('Daily Summary(Airtel)'!$M$4:$M$1048576,'Daily Summary(Airtel)'!$B$4:$B$1048576,B25) -> 2687 | J25: =SUMIFS('Daily Summary(Airtel)'!$N$4:$N$1048576,'Daily Summary(Airtel)'!$B$4:$B$1048576,B25) -> 1095073.8 | K25: =SUMIFS('Daily Summary(Airtel)'!$O$4:$O$1048576,'Daily Summary(Airtel)'!$B$4:$B$1048576,B25) -> 2428 | L25: 1016112.6 | M25: 1016112.6 | N25: 1016112.6 | O25: 1016112.6
B26: Aug-2024 | C26: 3805 | D26: =5%*F26 -> 182176 | E26: =SUMIFS('Daily Summary(Airtel)'!$F$4:$F$1048576,'Daily Summary(Airtel)'!$B$4:$B$1048576,B26) -> 9849 | F26: =SUMIFS('Daily Summary(Airtel)'!$G$4:$G$1048576,'Daily Summary(Airtel)'!$B$4:$B$1048576,B26) -> 3643520 | G26: =SUMIFS('Daily Summary(Airtel)'!$H$4:$H$1048576,'Daily Summary(Airtel)'!$B$4:$B$1048576,B26) -> 9748 | H26: =F26/E26 -> 369.93806 | I26: =SUMIFS('Daily Summary(Airtel)'!$M$4:$M$1048576,'Daily Summary(Airtel)'!$B$4:$B$1048576,B26) -> 6183 | J26: =SUMIFS('Daily Summary(Airtel)'!$N$4:$N$1048576,'Daily Summary(Airtel)'!$B$4:$B$1048576,B26) -> 1840936.3 | K26: =SUMIFS('Daily Summary(Airtel)'!$O$4:$O$1048576,'Daily Summary(Airtel)'!$B$4:$B$1048576,B26) -> 5638 | L26: 2109326.5 | M26: 2109326.5 | N26: 2109326.5 | O26: 2109326.5
B27: Sept-2024 | C27: 2817 | D27: =5%*F27 -> 228322.7 | E27: =SUMIFS('Daily Summary(Airtel)'!$F$4:$F$1048576,'Daily Summary(Airtel)'!$B$4:$B$1048576,B27) -> 10626 | F27: =SUMIFS('Daily Summary(Airtel)'!$G$4:$G$1048576,'Daily Summary(Airtel)'!$B$4:$B$1048576,B27) -> 4566454 | G27: =SUMIFS('Daily Summary(Airtel)'!$H$4:$H$1048576,'Daily Summary(Airtel)'!$B$4:$B$1048576,B27) -> 10470 | H27: =F27/E27 -> 429.74346 | I27: =SUMIFS('Daily Summary(Airtel)'!$M$4:$M$1048576,'Daily Summary(Airtel)'!$B$4:$B$1048576,B27) -> 9007 | J27: =SUMIFS('Daily Summary(Airtel)'!$N$4:$N$1048576,'Daily Summary(Airtel)'!$B$4:$B$1048576,B27) -> 2678482.9 | K27: =SUMIFS('Daily Summary(Airtel)'!$O$4:$O$1048576,'Daily Summary(Airtel)'!$B$4:$B$1048576,B27) -> 8065 | L27: 2197343.3 | M27: 2197343.3 | N27: 2197343.3 | O27: 2197343.3
B28: Oct-2024 | C28: 5131 | D28: =5%*F28 -> 147013.9 | E28: =SUMIFS('Daily Summary(Airtel)'!$F$4:$F$1048576,'Daily Summary(Airtel)'!$B$4:$B$1048576,B28) -> 9325 | F28: =SUMIFS('Daily Summary(Airtel)'!$G$4:$G$1048576,'Daily Summary(Airtel)'!$B$4:$B$1048576,B28) -> 2940278 | G28: =SUMIFS('Daily Summary(Airtel)'!$H$4:$H$1048576,'Daily Summary(Airtel)'!$B$4:$B$1048576,B28) -> 9196 | H28: =F28/E28 -> 315.31131 | I28: =SUMIFS('Daily Summary(Airtel)'!$M$4:$M$1048576,'Daily Summary(Airtel)'!$B$4:$B$1048576,B28) -> 7253 | J28: =SUMIFS('Daily Summary(Airtel)'!$N$4:$N$1048576,'Daily Summary(Airtel)'!$B$4:$B$1048576,B28) -> 1871769.7 | K28: =SUMIFS('Daily Summary(Airtel)'!$O$4:$O$1048576,'Daily Summary(Airtel)'!$B$4:$B$1048576,B28) -> 6550 | L28: 1243331.7 | M28: 1243331.7 | N28: 1243331.7 | O28: 1243331.7
B29: Nov-2024 | C29: 7683 | D29: =5%*F29 -> 42789.8 | E29: =SUMIFS('Daily Summary(Airtel)'!$F$4:$F$1048576,'Daily Summary(Airtel)'!$B$4:$B$1048576,B29) -> 8622 | F29: =SUMIFS('Daily Summary(Airtel)'!$G$4:$G$1048576,'Daily Summary(Airtel)'!$B$4:$B$1048576,B29) -> 855796 | G29: =SUMIFS('Daily Summary(Airtel)'!$H$4:$H$1048576,'Daily Summary(Airtel)'!$B$4:$B$1048576,B29) -> 8392 | H29: =F29/E29 -> 99.257249 | I29: =SUMIFS('Daily Summary(Airtel)'!$M$4:$M$1048576,'Daily Summary(Airtel)'!$B$4:$B$1048576,B29) -> 5274 | J29: =SUMIFS('Daily Summary(Airtel)'!$N$4:$N$1048576,'Daily Summary(Airtel)'!$B$4:$B$1048576,B29) -> 384696.84 | K29: =SUMIFS('Daily Summary(Airtel)'!$O$4:$O$1048576,'Daily Summary(Airtel)'!$B$4:$B$1048576,B29) -> 4859 | L29: 545898.18 | M29: 545898.24 | N29: 545898.24 | O29: 545898.18
B30: Dec-2024 | C30: 7586 | D30: =5%*F30 -> 271969.2 | E30: =SUMIFS('Daily Summary(Airtel)'!$F$4:$F$1048576,'Daily Summary(Airtel)'!$B$4:$B$1048576,B30) -> 17965 | F30: =SUMIFS('Daily Summary(Airtel)'!$G$4:$G$1048576,'Daily Summary(Airtel)'!$B$4:$B$1048576,B30) -> 5439384 | G30: =SUMIFS('Daily Summary(Airtel)'!$H$4:$H$1048576,'Daily Summary(Airtel)'!$B$4:$B$1048576,B30) -> 17707 | H30: =F30/E30 -> 302.77673 | I30: =SUMIFS('Daily Summary(Airtel)'!$M$4:$M$1048576,'Daily Summary(Airtel)'!$B$4:$B$1048576,B30) -> 14968 | J30: =SUMIFS('Daily Summary(Airtel)'!$N$4:$N$1048576,'Daily Summary(Airtel)'!$B$4:$B$1048576,B30) -> 3410525.7 | K30: =SUMIFS('Daily Summary(Airtel)'!$O$4:$O$1048576,'Daily Summary(Airtel)'!$B$4:$B$1048576,B30) -> 13162 | L30: 2324742.5 | M30: 2324742.8 | N30: 2324742.8 | O30: 2324742.5
B31: Jan-2025 | C31: 6690 | D31: =5%*F31 -> 184047.4 | E31: =SUMIFS('Daily Summary(Airtel)'!$F$4:$F$1048576,'Daily Summary(Airtel)'!$B$4:$B$1048576,B31) -> 13951 | F31: =SUMIFS('Daily Summary(Airtel)'!$G$4:$G$1048576,'Daily Summary(Airtel)'!$B$4:$B$1048576,B31) -> 3680948 | G31: =SUMIFS('Daily Summary(Airtel)'!$H$4:$H$1048576,'Daily Summary(Airtel)'!$B$4:$B$1048576,B31) -> 13764 | H31: =F31/E31 -> 263.84833 | I31: =SUMIFS('Daily Summary(Airtel)'!$M$4:$M$1048576,'Daily Summary(Airtel)'!$B$4:$B$1048576,B31) -> 11087 | J31: =SUMIFS('Daily Summary(Airtel)'!$N$4:$N$1048576,'Daily Summary(Airtel)'!$B$4:$B$1048576,B31) -> 2444352 | K31: =SUMIFS('Daily Summary(Airtel)'!$O$4:$O$1048576,'Daily Summary(Airtel)'!$B$4:$B$1048576,B31) -> 10104 | L31: 1412231.5 | M31: 1412231.5 | N31: 1412231.5 | O31: 1412231.5
B32: Feb-2025 | C32: 7092 | D32: =5%*F32 -> 161924.95 | E32: =SUMIFS('Daily Summary(Airtel)'!$F$4:$F$1048576,'Daily Summary(Airtel)'!$B$4:$B$1048576,B32) -> 13713 | F32: =SUMIFS('Daily Summary(Airtel)'!$G$4:$G$1048576,'Daily Summary(Airtel)'!$B$4:$B$1048576,B32) -> 3238499 | G32: =SUMIFS('Daily Summary(Airtel)'!$H$4:$H$1048576,'Daily Summary(Airtel)'!$B$4:$B$1048576,B32) -> 13503 | H32: =F32/E32 -> 236.16269 | I32: =SUMIFS('Daily Summary(Airtel)'!$M$4:$M$1048576,'Daily Summary(Airtel)'!$B$4:$B$1048576,B32) -> 10215 | J32: =SUMIFS('Daily Summary(Airtel)'!$N$4:$N$1048576,'Daily Summary(Airtel)'!$B$4:$B$1048576,B32) -> 2197723.3 | K32: =SUMIFS('Daily Summary(Airtel)'!$O$4:$O$1048576,'Daily Summary(Airtel)'!$B$4:$B$1048576,B32) -> 9403 | L32: 1179633.1 | M32: 1179633.1 | N32: 1179633.1 | O32: 1179633.1
B33: Mar-2025 | C33: 8376 | D33: =5%*F33 -> 189528.79 | E33: =SUMIFS('Daily Summary(Airtel)'!$F$4:$F$1048576,'Daily Summary(Airtel)'!$B$4:$B$1048576,B33) -> 16502 | F33: =SUMIFS('Daily Summary(Airtel)'!$G$4:$G$1048576,'Daily Summary(Airtel)'!$B$4:$B$1048576,B33) -> 3790575.9 | G33: =SUMIFS('Daily Summary(Airtel)'!$H$4:$H$1048576,'Daily Summary(Airtel)'!$B$4:$B$1048576,B33) -> 16291 | H33: =F33/E33 -> 229.70403 | I33: =SUMIFS('Daily Summary(Airtel)'!$M$4:$M$1048576,'Daily Summary(Airtel)'!$B$4:$B$1048576,B33) -> 11900 | J33: =SUMIFS('Daily Summary(Airtel)'!$N$4:$N$1048576,'Daily Summary(Airtel)'!$B$4:$B$1048576,B33) -> 2443256.6 | K33: =SUMIFS('Daily Summary(Airtel)'!$O$4:$O$1048576,'Daily Summary(Airtel)'!$B$4:$B$1048576,B33) -> 10921 | L33: 1515940.9 | M33: 1515940.9 | N33: 1515940.9 | O33: 1515940.9
B34: Apr-2025 | C34: 7253 | D34: =5%*F34 -> 159140.4 | E34: =SUMIFS('Daily Summary(Airtel)'!$F$4:$F$1048576,'Daily Summary(Airtel)'!$B$4:$B$1048576,B34) -> 14201 | F34: =SUMIFS('Daily Summary(Airtel)'!$G$4:$G$1048576,'Daily Summary(Airtel)'!$B$4:$B$1048576,B34) -> 3182808 | G34: =SUMIFS('Daily Summary(Airtel)'!$H$4:$H$1048576,'Daily Summary(Airtel)'!$B$4:$B$1048576,B34) -> 13955 | H34: =F34/E34 -> 224.12562 | I34: =SUMIFS('Daily Summary(Airtel)'!$M$4:$M$1048576,'Daily Summary(Airtel)'!$B$4:$B$1048576,B34) -> 10455 | J34: =SUMIFS('Daily Summary(Airtel)'!$N$4:$N$1048576,'Daily Summary(Airtel)'!$B$4:$B$1048576,B34) -> 2079059.8 | K34: =SUMIFS('Daily Summary(Airtel)'!$O$4:$O$1048576,'Daily Summary(Airtel)'!$B$4:$B$1048576,B34) -> 9577 | L34: 1233635.4 | M34: 1233635.4 | N34: 1233635.4 | O34: 1233635.4
B35: May-2025 | C35: 556 | D35: =5%*F35 -> 127717.15 | E35: =SUMIFS('Daily Summary(Airtel)'!$F$4:$F$1048576,'Daily Summary(Airtel)'!$B$4:$B$1048576,B35) -> 8078 | F35: =SUMIFS('Daily Summary(Airtel)'!$G$4:$G$1048576,'Daily Summary(Airtel)'!$B$4:$B$1048576,B35) -> 2554343 | G35: =SUMIFS('Daily Summary(Airtel)'!$H$4:$H$1048576,'Daily Summary(Airtel)'!$B$4:$B$1048576,B35) -> 7958 | H35: =F35/E35 -> 316.20983 | I35: =SUMIFS('Daily Summary(Airtel)'!$M$4:$M$1048576,'Daily Summary(Airtel)'!$B$4:$B$1048576,B35) -> 7760 | J35: =SUMIFS('Daily Summary(Airtel)'!$N$4:$N$1048576,'Daily Summary(Airtel)'!$B$4:$B$1048576,B35) -> 1856481 | K35: =SUMIFS('Daily Summary(Airtel)'!$O$4:$O$1048576,'Daily Summary(Airtel)'!$B$4:$B$1048576,B35) -> 6980 | L35: 775590.43 | M35: 775590.43 | N35: 775590.43 | O35: 775590.43
B36: Jun-2025 | C36: 7 | D36: =5%*F36 -> 109579.9 | E36: =SUMIFS('Daily Summary(Airtel)'!$F$4:$F$1048576,'Daily Summary(Airtel)'!$B$4:$B$1048576,B36) -> 5889 | F36: =SUMIFS('Daily Summary(Airtel)'!$G$4:$G$1048576,'Daily Summary(Airtel)'!$B$4:$B$1048576,B36) -> 2191598 | G36: =SUMIFS('Daily Summary(Airtel)'!$H$4:$H$1048576,'Daily Summary(Airtel)'!$B$4:$B$1048576,B36) -> 5806 | H36: =F36/E36 -> 372.15113 | I36: =SUMIFS('Daily Summary(Airtel)'!$M$4:$M$1048576,'Daily Summary(Airtel)'!$B$4:$B$1048576,B36) -> 6183 | J36: =SUMIFS('Daily Summary(Airtel)'!$N$4:$N$1048576,'Daily Summary(Airtel)'!$B$4:$B$1048576,B36) -> 1660378.4 | K36: =SUMIFS('Daily Summary(Airtel)'!$O$4:$O$1048576,'Daily Summary(Airtel)'!$B$4:$B$1048576,B36) -> 5548 | L36: 586507.63 | M36: 586507.63 | N36: 586507.63 | O36: 586507.63
... B38: Aug-2025 | C38: 5 | D38: =5%*F38 -> 95788.45 | E38: =SUMIFS('Daily Summary(Airtel)'!$F$4:$F$1048576,'Daily Summary(Airtel)'!$B$4:$B$1048576,B38) -> 4547 | F38: =SUMIFS('Daily Summary(Airtel)'!$G$4:$G$1048576,'Daily Summary(Airtel)'!$B$4:$B$1048576,B38) -> 1915769 | G38: =SUMIFS('Daily Summary(Airtel)'!$H$4:$H$1048576,'Daily Summary(Airtel)'!$B$4:$B$1048576,B38) -> 4482 | H38: =F38/E38 -> 421.32593 | I38: =SUMIFS('Daily Summary(Airtel)'!$M$4:$M$1048576,'Daily Summary(Airtel)'!$B$4:$B$1048576,B38) -> 4741 | J38: =SUMIFS('Daily Summary(Airtel)'!$N$4:$N$1048576,'Daily Summary(Airtel)'!$B$4:$B$1048576,B38) -> 1435479.4 | K38: =SUMIFS('Daily Summary(Airtel)'!$O$4:$O$1048576,'Daily Summary(Airtel)'!$B$4:$B$1048576,B38) -> 4383 | L38: 520575.61 | M38: 520575.61 | N38: 520575.61 | O38: 520575.61
B39: Sept-2025 | D39: =5%*F39 -> 83238.25 | E39: =SUMIFS('Daily Summary(Airtel)'!$F$4:$F$1048576,'Daily Summary(Airtel)'!$B$4:$B$1048576,B39) -> 3794 | F39: =SUMIFS('Daily Summary(Airtel)'!$G$4:$G$1048576,'Daily Summary(Airtel)'!$B$4:$B$1048576,B39) -> 1664765 | G39: =SUMIFS('Daily Summary(Airtel)'!$H$4:$H$1048576,'Daily Summary(Airtel)'!$B$4:$B$1048576,B39) -> 3752 | H39: =F39/E39 -> 438.78888 | I39: =SUMIFS('Daily Summary(Airtel)'!$M$4:$M$1048576,'Daily Summary(Airtel)'!$B$4:$B$1048576,B39) -> 4183 | J39: =SUMIFS('Daily Summary(Airtel)'!$N$4:$N$1048576,'Daily Summary(Airtel)'!$B$4:$B$1048576,B39) -> 1308717.7 | K39: =SUMIFS('Daily Summary(Airtel)'!$O$4:$O$1048576,'Daily Summary(Airtel)'!$B$4:$B$1048576,B39) -> 3826 | L39: 385168.74 | M39: 385168.74 | N39: 385168.74 | O39: 385168.74
B40: Oct-2025 | C40: 1 | D40: =5%*F40 -> 94699.55 | E40: =SUMIFS('Daily Summary(Airtel)'!$F$4:$F$1048576,'Daily Summary(Airtel)'!$B$4:$B$1048576,B40) -> 4290 | F40: =SUMIFS('Daily Summary(Airtel)'!$G$4:$G$1048576,'Daily Summary(Airtel)'!$B$4:$B$1048576,B40) -> 1893991 | G40: =SUMIFS('Daily Summary(Airtel)'!$H$4:$H$1048576,'Daily Summary(Airtel)'!$B$4:$B$1048576,B40) -> 4197 | H40: =F40/E40 -> 441.48974 | I40: =SUMIFS('Daily Summary(Airtel)'!$M$4:$M$1048576,'Daily Summary(Airtel)'!$B$4:$B$1048576,B40) -> 4569 | J40: =SUMIFS('Daily Summary(Airtel)'!$N$4:$N$1048576,'Daily Summary(Airtel)'!$B$4:$B$1048576,B40) -> 1428031.5 | K40: =SUMIFS('Daily Summary(Airtel)'!$O$4:$O$1048576,'Daily Summary(Airtel)'!$B$4:$B$1048576,B40) -> 4147 | L40: 496695.05 | M40: 496695.05 | N40: 496695.05 | O40: 496695.05
B41: Nov-2025 | C41: 1 | D41: =5%*F41 -> 90302.8 | E41: =SUMIFS('Daily Summary(Airtel)'!$F$4:$F$1048576,'Daily Summary(Airtel)'!$B$4:$B$1048576,B41) -> 4073 | F41: =SUMIFS('Daily Summary(Airtel)'!$G$4:$G$1048576,'Daily Summary(Airtel)'!$B$4:$B$1048576,B41) -> 1806056 | G41: =SUMIFS('Daily Summary(Airtel)'!$H$4:$H$1048576,'Daily Summary(Airtel)'!$B$4:$B$1048576,B41) -> 4027 | H41: =F41/E41 -> 443.42156 | I41: =SUMIFS('Daily Summary(Airtel)'!$M$4:$M$1048576,'Daily Summary(Airtel)'!$B$4:$B$1048576,B41) -> 4130 | J41: =SUMIFS('Daily Summary(Airtel)'!$N$4:$N$1048576,'Daily Summary(Airtel)'!$B$4:$B$1048576,B41) -> 1366407.2 | K41: =SUMIFS('Daily Summary(Airtel)'!$O$4:$O$1048576,'Daily Summary(Airtel)'!$B$4:$B$1048576,B41) -> 3818 | L41: 465453.56 | M41: 465453.56 | N41: 465453.56 | O41: 465453.56
B42: Dec-2025 | C42: 1 | D42: =5%*F42 -> 79459.1 | E42: =SUMIFS('Daily Summary(Airtel)'!$F$4:$F$1048576,'Daily Summary(Airtel)'!$B$4:$B$1048576,B42) -> 3478 | F42: =SUMIFS('Daily Summary(Airtel)'!$G$4:$G$1048576,'Daily Summary(Airtel)'!$B$4:$B$1048576,B42) -> 1589182 | G42: =SUMIFS('Daily Summary(Airtel)'!$H$4:$H$1048576,'Daily Summary(Airtel)'!$B$4:$B$1048576,B42) -> 3418 | H42: =F42/E42 -> 456.92409 | I42: =SUMIFS('Daily Summary(Airtel)'!$M$4:$M$1048576,'Daily Summary(Airtel)'!$B$4:$B$1048576,B42) -> 3616 | J42: =SUMIFS('Daily Summary(Airtel)'!$N$4:$N$1048576,'Daily Summary(Airtel)'!$B$4:$B$1048576,B42) -> 1228659.4 | K42: =SUMIFS('Daily Summary(Airtel)'!$O$4:$O$1048576,'Daily Summary(Airtel)'!$B$4:$B$1048576,B42) -> 3342 | L42: 378444.06 | M42: 378444.06 | N42: 378444.06 | O42: 378444.06
B43: Jan-2026 | D43: =5%*F43 -> 90807.05 | E43: =SUMIFS('Daily Summary(Airtel)'!$F$4:$F$1048576,'Daily Summary(Airtel)'!$B$4:$B$1048576,B43) -> 3924 | F43: =SUMIFS('Daily Summary(Airtel)'!$G$4:$G$1048576,'Daily Summary(Airtel)'!$B$4:$B$1048576,B43) -> 1816141 | G43: =SUMIFS('Daily Summary(Airtel)'!$H$4:$H$1048576,'Daily Summary(Airtel)'!$B$4:$B$1048576,B43) -> 3834 | H43: =F43/E43 -> 462.829 | I43: =SUMIFS('Daily Summary(Airtel)'!$M$4:$M$1048576,'Daily Summary(Airtel)'!$B$4:$B$1048576,B43) -> 3883 | J43: =SUMIFS('Daily Summary(Airtel)'!$N$4:$N$1048576,'Daily Summary(Airtel)'!$B$4:$B$1048576,B43) -> 1297412.5 | K43: =SUMIFS('Daily Summary(Airtel)'!$O$4:$O$1048576,'Daily Summary(Airtel)'!$B$4:$B$1048576,B43) -> 3551 | L43: 535931.55 | M43: 535931.58 | N43: 535931.58 | O43: 535931.55
B44: Feb-2026 | D44: =5%*F44 -> 72005.45 | E44: =SUMIFS('Daily Summary(Airtel)'!$F$4:$F$1048576,'Daily Summary(Airtel)'!$B$4:$B$1048576,B44) -> 2991 | F44: =SUMIFS('Daily Summary(Airtel)'!$G$4:$G$1048576,'Daily Summary(Airtel)'!$B$4:$B$1048576,B44) -> 1440109 | G44: =SUMIFS('Daily Summary(Airtel)'!$H$4:$H$1048576,'Daily Summary(Airtel)'!$B$4:$B$1048576,B44) -> 2943 | H44: =F44/E44 -> 481.48078 | I44: =SUMIFS('Daily Summary(Airtel)'!$M$4:$M$1048576,'Daily Summary(Airtel)'!$B$4:$B$1048576,B44) -> 2827 | J44: =SUMIFS('Daily Summary(Airtel)'!$N$4:$N$1048576,'Daily Summary(Airtel)'!$B$4:$B$1048576,B44) -> 998535.87 | K44: =SUMIFS('Daily Summary(Airtel)'!$O$4:$O$1048576,'Daily Summary(Airtel)'!$B$4:$B$1048576,B44) -> 2552 | L44: 451822.29 | M44: 451822.29 | N44: 451822.29 | O44: 451822.29
B45: Mar-2026 | D45: =5%*F45 -> 72495.1 | E45: =SUMIFS('Daily Summary(Airtel)'!$F$4:$F$1048576,'Daily Summary(Airtel)'!$B$4:$B$1048576,B45) -> 2863 | F45: =SUMIFS('Daily Summary(Airtel)'!$G$4:$G$1048576,'Daily Summary(Airtel)'!$B$4:$B$1048576,B45) -> 1449902 | G45: =SUMIFS('Daily Summary(Airtel)'!$H$4:$H$1048576,'Daily Summary(Airtel)'!$B$4:$B$1048576,B45) -> 2846 | H45: =F45/E45 -> 506.42752 | I45: =SUMIFS('Daily Summary(Airtel)'!$M$4:$M$1048576,'Daily Summary(Airtel)'!$B$4:$B$1048576,B45) -> 2088 | J45: =SUMIFS('Daily Summary(Airtel)'!$N$4:$N$1048576,'Daily Summary(Airtel)'!$B$4:$B$1048576,B45) -> 739632.63 | K45: =SUMIFS('Daily Summary(Airtel)'!$O$4:$O$1048576,'Daily Summary(Airtel)'!$B$4:$B$1048576,B45) -> 1877 | L45: 165913.23 | M45: 707661.29 | N45: 707661.29 | O45: 165913.23
B46: TOTAL | C46: 1180338 | D46: =SUM(D5:D45) -> 34577388 | E46: =SUM(E5:E45) -> 1416450 | F46: =SUM(F5:F45) -> 6.9154776e+08 | G46: 1407852 | H46: =F46/E46 -> 488.22603 | I46: =SUM(I5:I45) -> 683601 | J46: =SUM(J5:J45) -> 2.1931003e+08 | K46: 209436 | L46: =SUM(L5:L45) -> 6.1674485e+08 | M46: =SUM(M5:M45) -> 6.1728662e+08 | N46: 375702.28

Sheet Monthly Summary (Telkom)
B2: Individuals
C3: OPT-Ins | D3: Mandatory Svgs | E3: DISBURSEMENTS | I3: REPAYMENTS | L3: PERFORMANCE
B4: ID_MNTH | C4: CUST_BASE | D4: TXN_VAL | E4: TXN_VOL | F4: TXN_VAL | G4: CUST_COUNT | H4: AV_TICKET_SIZE | I4: TXN_VOL | J4: TXN_VAL | K4: CUST_COUNT | L4: DUE | M4: OUTSTANDING
B5: Nov-2022 | C5: 11331 | D5: =5%*F5 -> 23282.05 | E5: =SUMIFS('Daily Summary(Telkom)'!$F$4:$F$1048576,'Daily Summary(Telkom)'!$B$4:$B$1048576,B5) -> 966 | F5: =SUMIFS('Daily Summary(Telkom)'!$G$4:$G$1048576,'Daily Summary(Telkom)'!$B$4:$B$1048576,B5) -> 465641 | G5: =SUMIFS('Daily Summary(Telkom)'!$H$4:$H$1048576,'Daily Summary(Telkom)'!$B$4:$B$1048576,B5) -> 956 | H5: =F5/E5 -> 482.03002 | I5: =SUMIFS('Daily Summary(Telkom)'!$M$4:$M$1048576,'Daily Summary(Telkom)'!$B$4:$B$1048576,B5) -> 326 | J5: =SUMIFS('Daily Summary(Telkom)'!$N$4:$N$1048576,'Daily Summary(Telkom)'!$B$4:$B$1048576,B5) -> 116514.92 | K5: =SUMIFS('Daily Summary(Telkom)'!$O$4:$O$1048576,'Daily Summary(Telkom)'!$B$4:$B$1048576,B5) -> 299 | L5: =SUMIFS('Daily Summary(Telkom)'!$S$4:$S$1048576,'Daily Summary(Telkom)'!$B$4:$B$1048576,B5) -> 462182.85 | M5: =SUMIFS('Daily Summary(Telkom)'!$J$4:$J$1048576,'Daily Summary(Telkom)'!$B$4:$B$1048576,B5) -> 462184.39
B6: Dec-2022 | C6: 128192 | D6: =5%*F6 -> 2141127.1 | E6: =SUMIFS('Daily Summary(Telkom)'!$F$4:$F$1048576,'Daily Summary(Telkom)'!$B$4:$B$1048576,B6) -> 86945 | F6: =SUMIFS('Daily Summary(Telkom)'!$G$4:$G$1048576,'Daily Summary(Telkom)'!$B$4:$B$1048576,B6) -> 42822542 | G6: =SUMIFS('Daily Summary(Telkom)'!$H$4:$H$1048576,'Daily Summary(Telkom)'!$B$4:$B$1048576,B6) -> 86526 | H6: =F6/E6 -> 492.5245 | I6: =SUMIFS('Daily Summary(Telkom)'!$M$4:$M$1048576,'Daily Summary(Telkom)'!$B$4:$B$1048576,B6) -> 8644 | J6: =SUMIFS('Daily Summary(Telkom)'!$N$4:$N$1048576,'Daily Summary(Telkom)'!$B$4:$B$1048576,B6) -> 3159515.4 | K6: =SUMIFS('Daily Summary(Telkom)'!$O$4:$O$1048576,'Daily Summary(Telkom)'!$B$4:$B$1048576,B6) -> 8028 | L6: =SUMIFS('Daily Summary(Telkom)'!$S$4:$S$1048576,'Daily Summary(Telkom)'!$B$4:$B$1048576,B6) -> 52276200 | M6: =SUMIFS('Daily Summary(Telkom)'!$J$4:$J$1048576,'Daily Summary(Telkom)'!$B$4:$B$1048576,B6) -> 52276200
B7: Jan-2023 | C7: 1504 | D7: =5%*F7 -> 93495.675 | E7: =SUMIFS('Daily Summary(Telkom)'!$F$4:$F$1048576,'Daily Summary(Telkom)'!$B$4:$B$1048576,B7) -> 3951 | F7: =SUMIFS('Daily Summary(Telkom)'!$G$4:$G$1048576,'Daily Summary(Telkom)'!$B$4:$B$1048576,B7) -> 1869913.5 | G7: =SUMIFS('Daily Summary(Telkom)'!$H$4:$H$1048576,'Daily Summary(Telkom)'!$B$4:$B$1048576,B7) -> 3899 | H7: =F7/E7 -> 473.27601 | I7: =SUMIFS('Daily Summary(Telkom)'!$M$4:$M$1048576,'Daily Summary(Telkom)'!$B$4:$B$1048576,B7) -> 1841 | J7: =SUMIFS('Daily Summary(Telkom)'!$N$4:$N$1048576,'Daily Summary(Telkom)'!$B$4:$B$1048576,B7) -> 729981.32 | K7: =SUMIFS('Daily Summary(Telkom)'!$O$4:$O$1048576,'Daily Summary(Telkom)'!$B$4:$B$1048576,B7) -> 1734 | L7: =SUMIFS('Daily Summary(Telkom)'!$S$4:$S$1048576,'Daily Summary(Telkom)'!$B$4:$B$1048576,B7) -> 1508638.4 | M7: =SUMIFS('Daily Summary(Telkom)'!$J$4:$J$1048576,'Daily Summary(Telkom)'!$B$4:$B$1048576,B7) -> 1508638.4
B8: Feb-2023 | C8: 1161 | D8: =5%*F8 -> 81393.339 | E8: =SUMIFS('Daily Summary(Telkom)'!$F$4:$F$1048576,'Daily Summary(Telkom)'!$B$4:$B$1048576,B8) -> 3241 | F8: =SUMIFS('Daily Summary(Telkom)'!$G$4:$G$1048576,'Daily Summary(Telkom)'!$B$4:$B$1048576,B8) -> 1627866.8 | G8: =SUMIFS('Daily Summary(Telkom)'!$H$4:$H$1048576,'Daily Summary(Telkom)'!$B$4:$B$1048576,B8) -> 3203 | H8: =F8/E8 -> 502.273 | I8: =SUMIFS('Daily Summary(Telkom)'!$M$4:$M$1048576,'Daily Summary(Telkom)'!$B$4:$B$1048576,B8) -> 1896 | J8: =SUMIFS('Daily Summary(Telkom)'!$N$4:$N$1048576,'Daily Summary(Telkom)'!$B$4:$B$1048576,B8) -> 773134.04 | K8: =SUMIFS('Daily Summary(Telkom)'!$O$4:$O$1048576,'Daily Summary(Telkom)'!$B$4:$B$1048576,B8) -> 1735 | L8: =SUMIFS('Daily Summary(Telkom)'!$S$4:$S$1048576,'Daily Summary(Telkom)'!$B$4:$B$1048576,B8) -> 1124352.8 | M8: =SUMIFS('Daily Summary(Telkom)'!$J$4:$J$1048576,'Daily Summary(Telkom)'!$B$4:$B$1048576,B8) -> 1124352.8
B9: Mar-2023 | C9: 3828 | D9: =5%*F9 -> 112463.4 | E9: =SUMIFS('Daily Summary(Telkom)'!$F$4:$F$1048576,'Daily Summary(Telkom)'!$B$4:$B$1048576,B9) -> 4335 | F9: =SUMIFS('Daily Summary(Telkom)'!$G$4:$G$1048576,'Daily Summary(Telkom)'!$B$4:$B$1048576,B9) -> 2249268 | G9: =SUMIFS('Daily Summary(Telkom)'!$H$4:$H$1048576,'Daily Summary(Telkom)'!$B$4:$B$1048576,B9) -> 4305 | H9: =F9/E9 -> 518.86228 | I9: =SUMIFS('Daily Summary(Telkom)'!$M$4:$M$1048576,'Daily Summary(Telkom)'!$B$4:$B$1048576,B9) -> 2257 | J9: =SUMIFS('Daily Summary(Telkom)'!$N$4:$N$1048576,'Daily Summary(Telkom)'!$B$4:$B$1048576,B9) -> 864262.48 | K9: =SUMIFS('Daily Summary(Telkom)'!$O$4:$O$1048576,'Daily Summary(Telkom)'!$B$4:$B$1048576,B9) -> 2059 | L9: =SUMIFS('Daily Summary(Telkom)'!$S$4:$S$1048576,'Daily Summary(Telkom)'!$B$4:$B$1048576,B9) -> 1809800.2 | M9: =SUMIFS('Daily Summary(Telkom)'!$J$4:$J$1048576,'Daily Summary(Telkom)'!$B$4:$B$1048576,B9) -> 1809801.4
B10: Apr-2023 | C10: 1710 | D10: =5%*F10 -> 71652.75 | E10: =SUMIFS('Daily Summary(Telkom)'!$F$4:$F$1048576,'Daily Summary(Telkom)'!$B$4:$B$1048576,B10) -> 2750 | F10: =SUMIFS('Daily Summary(Telkom)'!$G$4:$G$1048576,'Daily Summary(Telkom)'!$B$4:$B$1048576,B10) -> 1433055 | G10: =SUMIFS('Daily Summary(Telkom)'!$H$4:$H$1048576,'Daily Summary(Telkom)'!$B$4:$B$1048576,B10) -> 2744 | H10: =F10/E10 -> 521.11091 | I10: =SUMIFS('Daily Summary(Telkom)'!$M$4:$M$1048576,'Daily Summary(Telkom)'!$B$4:$B$1048576,B10) -> 1420 | J10: =SUMIFS('Daily Summary(Telkom)'!$N$4:$N$1048576,'Daily Summary(Telkom)'!$B$4:$B$1048576,B10) -> 573488.16 | K10: =SUMIFS('Daily Summary(Telkom)'!$O$4:$O$1048576,'Daily Summary(Telkom)'!$B$4:$B$1048576,B10) -> 1295 | L10: =SUMIFS('Daily Summary(Telkom)'!$S$4:$S$1048576,'Daily Summary(Telkom)'!$B$4:$B$1048576,B10) -> 1114705.7 | M10: =SUMIFS('Daily Summary(Telkom)'!$J$4:$J$1048576,'Daily Summary(Telkom)'!$B$4:$B$1048576,B10) -> 1114705.8
B11: May-2023 | C11: 862 | D11: =5%*F11 -> 51225.7 | E11: =SUMIFS('Daily Summary(Telkom)'!$F$4:$F$1048576,'Daily Summary(Telkom)'!$B$4:$B$1048576,B11) -> 1907 | F11: =SUMIFS('Daily Summary(Telkom)'!$G$4:$G$1048576,'Daily Summary(Telkom)'!$B$4:$B$1048576,B11) -> 1024514 | G11: =SUMIFS('Daily Summary(Telkom)'!$H$4:$H$1048576,'Daily Summary(Telkom)'!$B$4:$B$1048576,B11) -> 1904 | H11: =F11/E11 -> 537.23859 | I11: =SUMIFS('Daily Summary(Telkom)'!$M$4:$M$1048576,'Daily Summary(Telkom)'!$B$4:$B$1048576,B11) -> 1121 | J11: =SUMIFS('Daily Summary(Telkom)'!$N$4:$N$1048576,'Daily Summary(Telkom)'!$B$4:$B$1048576,B11) -> 478666.68 | K11: =SUMIFS('Daily Summary(Telkom)'!$O$4:$O$1048576,'Daily Summary(Telkom)'!$B$4:$B$1048576,B11) -> 1036 | L11: =SUMIFS('Daily Summary(Telkom)'!$S$4:$S$1048576,'Daily Summary(Telkom)'!$B$4:$B$1048576,B11) -> 704049.81 | M11: =SUMIFS('Daily Summary(Telkom)'!$J$4:$J$1048576,'Daily Summary(Telkom)'!$B$4:$B$1048576,B11) -> 704049.81
B12: Jun-2023 | C12: 1182 | D12: =5%*F12 -> 48002.4 | E12: =SUMIFS('Daily Summary(Telkom)'!$F$4:$F$1048576,'Daily Summary(Telkom)'!$B$4:$B$1048576,B12) -> 1820 | F12: =SUMIFS('Daily Summary(Telkom)'!$G$4:$G$1048576,'Daily Summary(Telkom)'!$B$4:$B$1048576,B12) -> 960048 | G12: =SUMIFS('Daily Summary(Telkom)'!$H$4:$H$1048576,'Daily Summary(Telkom)'!$B$4:$B$1048576,B12) -> 1819 | H12: =F12/E12 -> 527.4989 | I12: =SUMIFS('Daily Summary(Telkom)'!$M$4:$M$1048576,'Daily Summary(Telkom)'!$B$4:$B$1048576,B12) -> 1051 | J12: =SUMIFS('Daily Summary(Telkom)'!$N$4:$N$1048576,'Daily Summary(Telkom)'!$B$4:$B$1048576,B12) -> 429820.11 | K12: =SUMIFS('Daily Summary(Telkom)'!$O$4:$O$1048576,'Daily Summary(Telkom)'!$B$4:$B$1048576,B12) -> 980 | L12: =SUMIFS('Daily Summary(Telkom)'!$S$4:$S$1048576,'Daily Summary(Telkom)'!$B$4:$B$1048576,B12) -> 681872.53 | M12: =SUMIFS('Daily Summary(Telkom)'!$J$4:$J$1048576,'Daily Summary(Telkom)'!$B$4:$B$1048576,B12) -> 681872.53
B13: Jul-2023 | C13: 457 | D13: =5%*F13 -> 26453.1 | E13: =SUMIFS('Daily Summary(Telkom)'!$F$4:$F$1048576,'Daily Summary(Telkom)'!$B$4:$B$1048576,B13) -> 966 | F13: =SUMIFS('Daily Summary(Telkom)'!$G$4:$G$1048576,'Daily Summary(Telkom)'!$B$4:$B$1048576,B13) -> 529062 | G13: =SUMIFS('Daily Summary(Telkom)'!$H$4:$H$1048576,'Daily Summary(Telkom)'!$B$4:$B$1048576,B13) -> 964 | H13: =F13/E13 -> 547.68323 | I13: =SUMIFS('Daily Summary(Telkom)'!$M$4:$M$1048576,'Daily Summary(Telkom)'!$B$4:$B$1048576,B13) -> 668 | J13: =SUMIFS('Daily Summary(Telkom)'!$N$4:$N$1048576,'Daily Summary(Telkom)'!$B$4:$B$1048576,B13) -> 296085.46 | K13: =SUMIFS('Daily Summary(Telkom)'!$O$4:$O$1048576,'Daily Summary(Telkom)'!$B$4:$B$1048576,B13) -> 631 | L13: =SUMIFS('Daily Summary(Telkom)'!$S$4:$S$1048576,'Daily Summary(Telkom)'!$B$4:$B$1048576,B13) -> 297447.21 | M13: =SUMIFS('Daily Summary(Telkom)'!$J$4:$J$1048576,'Daily Summary(Telkom)'!$B$4:$B$1048576,B13) -> 297447.21
B14: Aug-2023 | C14: 464 | D14: =5%*F14 -> 23755.85 | E14: =SUMIFS('Daily Summary(Telkom)'!$F$4:$F$1048576,'Daily Summary(Telkom)'!$B$4:$B$1048576,B14) -> 879 | F14: =SUMIFS('Daily Summary(Telkom)'!$G$4:$G$1048576,'Daily Summary(Telkom)'!$B$4:$B$1048576,B14) -> 475117 | G14: =SUMIFS('Daily Summary(Telkom)'!$H$4:$H$1048576,'Daily Summary(Telkom)'!$B$4:$B$1048576,B14) -> 871 | H14: =F14/E14 -> 540.51991 | I14: =SUMIFS('Daily Summary(Telkom)'!$M$4:$M$1048576,'Daily Summary(Telkom)'!$B$4:$B$1048576,B14) -> 535 | J14: =SUMIFS('Daily Summary(Telkom)'!$N$4:$N$1048576,'Daily Summary(Telkom)'!$B$4:$B$1048576,B14) -> 240428.76 | K14: =SUMIFS('Daily Summary(Telkom)'!$O$4:$O$1048576,'Daily Summary(Telkom)'!$B$4:$B$1048576,B14) -> 496 | L14: =SUMIFS('Daily Summary(Telkom)'!$S$4:$S$1048576,'Daily Summary(Telkom)'!$B$4:$B$1048576,B14) -> 297083.66 | M14: =SUMIFS('Daily Summary(Telkom)'!$J$4:$J$1048576,'Daily Summary(Telkom)'!$B$4:$B$1048576,B14) -> 297083.66
B15: Sept-2023 | C15: 457 | D15: =5%*F15 -> 20896.95 | E15: =SUMIFS('Daily Summary(Telkom)'!$F$4:$F$1048576,'Daily Summary(Telkom)'!$B$4:$B$1048576,B15) -> 772 | F15: =SUMIFS('Daily Summary(Telkom)'!$G$4:$G$1048576,'Daily Summary(Telkom)'!$B$4:$B$1048576,B15) -> 417939 | G15: =SUMIFS('Daily Summary(Telkom)'!$H$4:$H$1048576,'Daily Summary(Telkom)'!$B$4:$B$1048576,B15) -> 769 | H15: =F15/E15 -> 541.37176 | I15: =SUMIFS('Daily Summary(Telkom)'!$M$4:$M$1048576,'Daily Summary(Telkom)'!$B$4:$B$1048576,B15) -> 484 | J15: =SUMIFS('Daily Summary(Telkom)'!$N$4:$N$1048576,'Daily Summary(Telkom)'!$B$4:$B$1048576,B15) -> 225778.86 | K15: =SUMIFS('Daily Summary(Telkom)'!$O$4:$O$1048576,'Daily Summary(Telkom)'!$B$4:$B$1048576,B15) -> 462 | L15: =SUMIFS('Daily Summary(Telkom)'!$S$4:$S$1048576,'Daily Summary(Telkom)'!$B$4:$B$1048576,B15) -> 242188.65 | M15: =SUMIFS('Daily Summary(Telkom)'!$J$4:$J$1048576,'Daily Summary(Telkom)'!$B$4:$B$1048576,B15) -> 242188.65
B16: Oct-2023 | C16: 445 | D16: =5%*F16 -> 20111.25 | E16: =SUMIFS('Daily Summary(Telkom)'!$F$4:$F$1048576,'Daily Summary(Telkom)'!$B$4:$B$1048576,B16) -> 741 | F16: =SUMIFS('Daily Summary(Telkom)'!$G$4:$G$1048576,'Daily Summary(Telkom)'!$B$4:$B$1048576,B16) -> 402225 | G16: =SUMIFS('Daily Summary(Telkom)'!$H$4:$H$1048576,'Daily Summary(Telkom)'!$B$4:$B$1048576,B16) -> 741 | H16: =F16/E16 -> 542.81377 | I16: =SUMIFS('Daily Summary(Telkom)'!$M$4:$M$1048576,'Daily Summary(Telkom)'!$B$4:$B$1048576,B16) -> 448 | J16: =SUMIFS('Daily Summary(Telkom)'!$N$4:$N$1048576,'Daily Summary(Telkom)'!$B$4:$B$1048576,B16) -> 213313.53 | K16: =SUMIFS('Daily Summary(Telkom)'!$O$4:$O$1048576,'Daily Summary(Telkom)'!$B$4:$B$1048576,B16) -> 429 | L16: =SUMIFS('Daily Summary(Telkom)'!$S$4:$S$1048576,'Daily Summary(Telkom)'!$B$4:$B$1048576,B16) -> 236019.14 | M16: =SUMIFS('Daily Summary(Telkom)'!$J$4:$J$1048576,'Daily Summary(Telkom)'!$B$4:$B$1048576,B16) -> 236019.14
... B31: Jan-2025 | C31: 267 | D31: =5%*F31 -> 15399.3 | E31: =SUMIFS('Daily Summary(Telkom)'!$F$4:$F$1048576,'Daily Summary(Telkom)'!$B$4:$B$1048576,B31) -> 526 | F31: =SUMIFS('Daily Summary(Telkom)'!$G$4:$G$1048576,'Daily Summary(Telkom)'!$B$4:$B$1048576,B31) -> 307986 | G31: =SUMIFS('Daily Summary(Telkom)'!$H$4:$H$1048576,'Daily Summary(Telkom)'!$B$4:$B$1048576,B31) -> 522 | H31: =F31/E31 -> 585.52471 | I31: =SUMIFS('Daily Summary(Telkom)'!$M$4:$M$1048576,'Daily Summary(Telkom)'!$B$4:$B$1048576,B31) -> 417 | J31: =SUMIFS('Daily Summary(Telkom)'!$N$4:$N$1048576,'Daily Summary(Telkom)'!$B$4:$B$1048576,B31) -> 215964.96 | K31: =SUMIFS('Daily Summary(Telkom)'!$O$4:$O$1048576,'Daily Summary(Telkom)'!$B$4:$B$1048576,B31) -> 378 | L31: =SUMIFS('Daily Summary(Telkom)'!$S$4:$S$1048576,'Daily Summary(Telkom)'!$B$4:$B$1048576,B31) -> 104659.36 | M31: =SUMIFS('Daily Summary(Telkom)'!$J$4:$J$1048576,'Daily Summary(Telkom)'!$B$4:$B$1048576,B31) -> 104659.36
B32: Feb-2025 | C32: 135 | D32: =5%*F32 -> 12466.7 | E32: =SUMIFS('Daily Summary(Telkom)'!$F$4:$F$1048576,'Daily Summary(Telkom)'!$B$4:$B$1048576,B32) -> 391 | F32: =SUMIFS('Daily Summary(Telkom)'!$G$4:$G$1048576,'Daily Summary(Telkom)'!$B$4:$B$1048576,B32) -> 249334 | G32: =SUMIFS('Daily Summary(Telkom)'!$H$4:$H$1048576,'Daily Summary(Telkom)'!$B$4:$B$1048576,B32) -> 389 | H32: =F32/E32 -> 637.68286 | I32: 336 | J32: 190172.71 | K32: 197 | L32: =SUMIFS('Daily Summary(Telkom)'!$S$4:$S$1048576,'Daily Summary(Telkom)'!$B$4:$B$1048576,B32) -> 66564.25 | M32: =SUMIFS('Daily Summary(Telkom)'!$J$4:$J$1048576,'Daily Summary(Telkom)'!$B$4:$B$1048576,B32) -> 66564.25
B33: Mar-2025 | C33: 183 | D33: =5%*F33 -> 12111.05 | E33: =SUMIFS('Daily Summary(Telkom)'!$F$4:$F$1048576,'Daily Summary(Telkom)'!$B$4:$B$1048576,B33) -> 405 | F33: =SUMIFS('Daily Summary(Telkom)'!$G$4:$G$1048576,'Daily Summary(Telkom)'!$B$4:$B$1048576,B33) -> 242221 | G33: =SUMIFS('Daily Summary(Telkom)'!$H$4:$H$1048576,'Daily Summary(Telkom)'!$B$4:$B$1048576,B33) -> 404 | H33: =F33/E33 -> 598.07654 | I33: 343 | J33: 179167.46 | K33: 167 | L33: =SUMIFS('Daily Summary(Telkom)'!$S$4:$S$1048576,'Daily Summary(Telkom)'!$B$4:$B$1048576,B33) -> 70410.32 | M33: =SUMIFS('Daily Summary(Telkom)'!$J$4:$J$1048576,'Daily Summary(Telkom)'!$B$4:$B$1048576,B33) -> 70410.32
B34: Apr-2025 | C34: 95 | D34: =5%*F34 -> 11238.8 | E34: =SUMIFS('Daily Summary(Telkom)'!$F$4:$F$1048576,'Daily Summary(Telkom)'!$B$4:$B$1048576,B34) -> 366 | F34: =SUMIFS('Daily Summary(Telkom)'!$G$4:$G$1048576,'Daily Summary(Telkom)'!$B$4:$B$1048576,B34) -> 224776 | G34: =SUMIFS('Daily Summary(Telkom)'!$H$4:$H$1048576,'Daily Summary(Telkom)'!$B$4:$B$1048576,B34) -> 363 | H34: =F34/E34 -> 614.14208 | I34: 390 | J34: 188884.06 | K34: 179 | L34: =SUMIFS('Daily Summary(Telkom)'!$S$4:$S$1048576,'Daily Summary(Telkom)'!$B$4:$B$1048576,B34) -> 40400.64 | M34: =SUMIFS('Daily Summary(Telkom)'!$J$4:$J$1048576,'Daily Summary(Telkom)'!$B$4:$B$1048576,B34) -> 40400.64
B35: May-2025 | C35: 110 | D35: =5%*F35 -> 11164.35 | E35: =SUMIFS('Daily Summary(Telkom)'!$F$4:$F$1048576,'Daily Summary(Telkom)'!$B$4:$B$1048576,B35) -> 336 | F35: =SUMIFS('Daily Summary(Telkom)'!$G$4:$G$1048576,'Daily Summary(Telkom)'!$B$4:$B$1048576,B35) -> 223287 | G35: =SUMIFS('Daily Summary(Telkom)'!$H$4:$H$1048576,'Daily Summary(Telkom)'!$B$4:$B$1048576,B35) -> 335 | H35: =F35/E35 -> 664.54464 | I35: 354 | J35: 183507.88 | K35: 161 | L35: =SUMIFS('Daily Summary(Telkom)'!$S$4:$S$1048576,'Daily Summary(Telkom)'!$B$4:$B$1048576,B35) -> 43168.75 | M35: =SUMIFS('Daily Summary(Telkom)'!$J$4:$J$1048576,'Daily Summary(Telkom)'!$B$4:$B$1048576,B35) -> 43168.75
B36: Jun-2025 | C36: 89 | D36: =5%*F36 -> 10399.9 | E36: =SUMIFS('Daily Summary(Telkom)'!$F$4:$F$1048576,'Daily Summary(Telkom)'!$B$4:$B$1048576,B36) -> 331 | F36: =SUMIFS('Daily Summary(Telkom)'!$G$4:$G$1048576,'Daily Summary(Telkom)'!$B$4:$B$1048576,B36) -> 207998 | G36: =SUMIFS('Daily Summary(Telkom)'!$H$4:$H$1048576,'Daily Summary(Telkom)'!$B$4:$B$1048576,B36) -> 284 | H36: =F36/E36 -> 628.39275 | I36: 337 | J36: 175561.02 | K36: 129 | L36: =SUMIFS('Daily Summary(Telkom)'!$S$4:$S$1048576,'Daily Summary(Telkom)'!$B$4:$B$1048576,B36) -> 35874.92 | M36: =SUMIFS('Daily Summary(Telkom)'!$J$4:$J$1048576,'Daily Summary(Telkom)'!$B$4:$B$1048576,B36) -> 35874.92
B37: Jul-2025 | C37: 24 | D37: =5%*F37 -> 5608.6 | E37: =SUMIFS('Daily Summary(Telkom)'!$F$4:$F$1048576,'Daily Summary(Telkom)'!$B$4:$B$1048576,B37) -> 152 | F37: =SUMIFS('Daily Summary(Telkom)'!$G$4:$G$1048576,'Daily Summary(Telkom)'!$B$4:$B$1048576,B37) -> 112172 | G37: =SUMIFS('Daily Summary(Telkom)'!$H$4:$H$1048576,'Daily Summary(Telkom)'!$B$4:$B$1048576,B37) -> 152 | H37: =F37/E37 -> 737.97368 | I37: 204 | J37: 101549.42 | K37: 96 | L37: =SUMIFS('Daily Summary(Telkom)'!$S$4:$S$1048576,'Daily Summary(Telkom)'!$B$4:$B$1048576,B37) -> 11879.65 | M37: =SUMIFS('Daily Summary(Telkom)'!$J$4:$J$1048576,'Daily Summary(Telkom)'!$B$4:$B$1048576,B37) -> 11879.65
B38: Aug-2025 | C38: 51 | D38: =5%*F38 -> 9128.3 | E38: =SUMIFS('Daily Summary(Telkom)'!$F$4:$F$1048576,'Daily Summary(Telkom)'!$B$4:$B$1048576,B38) -> 257 | F38: =SUMIFS('Daily Summary(Telkom)'!$G$4:$G$1048576,'Daily Summary(Telkom)'!$B$4:$B$1048576,B38) -> 182566 | G38: =SUMIFS('Daily Summary(Telkom)'!$H$4:$H$1048576,'Daily Summary(Telkom)'!$B$4:$B$1048576,B38) -> 252 | H38: =F38/E38 -> 710.37354 | I38: 295 | J38: 145851.67 | K38: 128 | L38: =SUMIFS('Daily Summary(Telkom)'!$S$4:$S$1048576,'Daily Summary(Telkom)'!$B$4:$B$1048576,B38) -> 39069.57 | M38: =SUMIFS('Daily Summary(Telkom)'!$J$4:$J$1048576,'Daily Summary(Telkom)'!$B$4:$B$1048576,B38) -> 39069.57
B39: Sept-2025 | C39: 44 | D39: =5%*F39 -> 8778.65 | E39: =SUMIFS('Daily Summary(Telkom)'!$F$4:$F$1048576,'Daily Summary(Telkom)'!$B$4:$B$1048576,B39) -> 238 | F39: =SUMIFS('Daily Summary(Telkom)'!$G$4:$G$1048576,'Daily Summary(Telkom)'!$B$4:$B$1048576,B39) -> 175573 | G39: =SUMIFS('Daily Summary(Telkom)'!$H$4:$H$1048576,'Daily Summary(Telkom)'!$B$4:$B$1048576,B39) -> 234 | H39: =F39/E39 -> 737.70168 | I39: 306 | J39: 153423.75 | K39: 119 | L39: =SUMIFS('Daily Summary(Telkom)'!$S$4:$S$1048576,'Daily Summary(Telkom)'!$B$4:$B$1048576,B39) -> 24095.43 | M39: =SUMIFS('Daily Summary(Telkom)'!$J$4:$J$1048576,'Daily Summary(Telkom)'!$B$4:$B$1048576,B39) -> 24095.43
B40: Oct-2025 | C40: 33 | D40: =5%*F40 -> 4558.5 | E40: =SUMIFS('Daily Summary(Telkom)'!$F$4:$F$1048576,'Daily Summary(Telkom)'!$B$4:$B$1048576,B40) -> 130 | F40: =SUMIFS('Daily Summary(Telkom)'!$G$4:$G$1048576,'Daily Summary(Telkom)'!$B$4:$B$1048576,B40) -> 91170 | G40: =SUMIFS('Daily Summary(Telkom)'!$H$4:$H$1048576,'Daily Summary(Telkom)'!$B$4:$B$1048576,B40) -> 126 | H40: =F40/E40 -> 701.30769 | I40: 142 | J40: 69466.64 | K40: 57 | L40: =SUMIFS('Daily Summary(Telkom)'!$S$4:$S$1048576,'Daily Summary(Telkom)'!$B$4:$B$1048576,B40) -> 18971.29 | M40: =SUMIFS('Daily Summary(Telkom)'!$J$4:$J$1048576,'Daily Summary(Telkom)'!$B$4:$B$1048576,B40) -> 18971.29
B41: Nov-2025 | C41: 13 | D41: =5%*F41 -> 2598 | E41: =SUMIFS('Daily Summary(Telkom)'!$F$4:$F$1048576,'Daily Summary(Telkom)'!$B$4:$B$1048576,B41) -> 80 | F41: =SUMIFS('Daily Summary(Telkom)'!$G$4:$G$1048576,'Daily Summary(Telkom)'!$B$4:$B$1048576,B41) -> 51960 | G41: =SUMIFS('Daily Summary(Telkom)'!$H$4:$H$1048576,'Daily Summary(Telkom)'!$B$4:$B$1048576,B41) -> 79 | H41: =F41/E41 -> 649.5 | I41: 64 | J41: 32194.3 | K41: 40 | L41: =SUMIFS('Daily Summary(Telkom)'!$S$4:$S$1048576,'Daily Summary(Telkom)'!$B$4:$B$1048576,B41) -> 15039.11 | M41: =SUMIFS('Daily Summary(Telkom)'!$J$4:$J$1048576,'Daily Summary(Telkom)'!$B$4:$B$1048576,B41) -> 15039.11
B42: Dec-2025 | C42: 8 | D42: =5%*F42 -> 1208 | E42: =SUMIFS('Daily Summary(Telkom)'!$F$4:$F$1048576,'Daily Summary(Telkom)'!$B$4:$B$1048576,B42) -> 34 | F42: =SUMIFS('Daily Summary(Telkom)'!$G$4:$G$1048576,'Daily Summary(Telkom)'!$B$4:$B$1048576,B42) -> 24160 | G42: =SUMIFS('Daily Summary(Telkom)'!$H$4:$H$1048576,'Daily Summary(Telkom)'!$B$4:$B$1048576,B42) -> 34 | H42: =F42/E42 -> 710.58824 | I42: 31 | J42: 13855.72 | K42: 19 | L42: =SUMIFS('Daily Summary(Telkom)'!$S$4:$S$1048576,'Daily Summary(Telkom)'!$B$4:$B$1048576,B42) -> 6404.18 | M42: =SUMIFS('Daily Summary(Telkom)'!$J$4:$J$1048576,'Daily Summary(Telkom)'!$B$4:$B$1048576,B42) -> 6404.18
B43: Jan-2026 | C43: 7 | D43: =5%*F43 -> 1850.5 | E43: =SUMIFS('Daily Summary(Telkom)'!$F$4:$F$1048576,'Daily Summary(Telkom)'!$B$4:$B$1048576,B43) -> 41 | F43: =SUMIFS('Daily Summary(Telkom)'!$G$4:$G$1048576,'Daily Summary(Telkom)'!$B$4:$B$1048576,B43) -> 37010 | G43: =SUMIFS('Daily Summary(Telkom)'!$H$4:$H$1048576,'Daily Summary(Telkom)'!$B$4:$B$1048576,B43) -> 41 | H43: =F43/E43 -> 902.68293 | I43: 31 | J43: 13855.72 | K43: 19 | L43: =SUMIFS('Daily Summary(Telkom)'!$S$4:$S$1048576,'Daily Summary(Telkom)'!$B$4:$B$1048576,B43) -> 14729.63 | M43: =SUMIFS('Daily Summary(Telkom)'!$J$4:$J$1048576,'Daily Summary(Telkom)'!$B$4:$B$1048576,B43) -> 14729.63
B44: Feb-2026 | C44: 26 | D44: =5%*F44 -> 2390.9 | E44: =SUMIFS('Daily Summary(Telkom)'!$F$4:$F$1048576,'Daily Summary(Telkom)'!$B$4:$B$1048576,B44) -> 88 | F44: =SUMIFS('Daily Summary(Telkom)'!$G$4:$G$1048576,'Daily Summary(Telkom)'!$B$4:$B$1048576,B44) -> 47818 | G44: =SUMIFS('Daily Summary(Telkom)'!$H$4:$H$1048576,'Daily Summary(Telkom)'!$B$4:$B$1048576,B44) -> 88 | H44: =F44/E44 -> 543.38636 | I44: 31 | J44: 13855.72 | K44: 19 | L44: =SUMIFS('Daily Summary(Telkom)'!$S$4:$S$1048576,'Daily Summary(Telkom)'!$B$4:$B$1048576,B44) -> 18591.24 | M44: =SUMIFS('Daily Summary(Telkom)'!$J$4:$J$1048576,'Daily Summary(Telkom)'!$B$4:$B$1048576,B44) -> 18591.24
B45: TOTAL | C45: 155493 | D45: =SUM(D5:D44) -> 3021325.6 | E45: =SUM(E5:E44) -> 118427 | F45: =SUM(F5:F44) -> 60426512 | G45: 117738 | H45: =F45/E45 -> 510.24269 | I45: =SUM(I5:I44) -> 28599 | J45: =SUM(J5:J44) -> 12672548 | K45: 8953 | L45: =SUM(L5:L44) -> 62555062 | M45: =SUM(M5:M44) -> 62555065

Sheet Daily Summary(Telkom)
A1: 46112
C2: LOAN TENURE | E2: Optins | F2: DISBURSEMENT | I2: OUTSTANDING LOANS | K2: REPAYMENT AT DAY LOAN DISBURSED | M2: REPAYMENTS | P2: INTEREST & PENALTY | R2: Mandatory Svgs | S2: OVERDUE
B3: ID_MNTH | C3: DT_INTN_DATE | D3: TENURE | E3: # Cust | F3: VOLUME | G3: VALUE | H3: SUB_COUNT | I3: VOLUME | J3: VALUE | K3: VOLUME | L3: VALUE | M3: VOLUME | N3: VALUE | O3: SUB_COUNT | P3: ACCRUED | Q3: PAID | R3: VALUE | S3: VALUE
B4: =TEXT(C4,"MMM-YYYY") -> Nov-2022 | C4: 44893 | D4: =$A$1-C4 -> 1219 | E4: 1 | R4: =G4*5% -> 0
B5: =TEXT(C5,"MMM-YYYY") -> Nov-2022 | C5: 44894 | D5: =$A$1-C5 -> 1218 | E5: 1 | F5: 2 | G5: 160 | H5: 1 | I5: 1 | J5: 209.15 | P5: 49.15 | Q5: 0 | R5: =G5*5% -> 8 | S5: 209.15
B6: =TEXT(C6,"MMM-YYYY") -> Nov-2022 | C6: 44895 | D6: =$A$1-C6 -> 1217 | E6: 11329 | F6: 964 | G6: 465481 | H6: 955 | I6: 924 | J6: 461975.24 | M6: 326 | N6: 116514.92 | O6: 299 | P6: 113007.73 | Q6: 1466.7 | R6: =G6*5% -> 23274.05 | S6: 461973.7
B7: =TEXT(C7,"MMM-YYYY") -> Dec-2022 | C7: 44896 | D7: =$A$1-C7 -> 1216 | E7: 23151 | F7: 7920 | G7: 3850692.3 | H7: 7845 | I7: 7667 | J7: 4151082.8 | M7: 1973 | N7: 711246.39 | O7: 1810 | P7: 1011636.6 | Q7: 9343.1 | R7: =G7*5% -> 192534.62 | S7: 4151082.5
B8: =TEXT(C8,"MMM-YYYY") -> Dec-2022 | C8: 44897 | D8: =$A$1-C8 -> 1215 | E8: 12462 | F8: 4280 | G8: 2048871 | H8: 4225 | I8: 4116 | J8: 2300852.7 | M8: 915 | N8: 308390.76 | O8: 848 | P8: 560372.47 | Q8: 5416.31 | R8: =G8*5% -> 102443.55 | S8: 2300852.7
B9: =TEXT(C9,"MMM-YYYY") -> Dec-2022 | C9: 44898 | D9: =$A$1-C9 -> 1214 | E9: 8477 | F9: 5495 | G9: 2692855 | H9: 5464 | I9: 5396 | J9: 3223282.1 | K9: 1 | L9: 470 | M9: 717 | N9: 250450.84 | O9: 663 | P9: 780877.9 | Q9: 3801.61 | R9: =G9*5% -> 134642.75 | S9: 3223282.1
B10: =TEXT(C10,"MMM-YYYY") -> Dec-2022 | C10: 44899 | D10: =$A$1-C10 -> 1213 | E10: 5834 | F10: 3950 | G10: 1922650 | H10: 3925 | I10: 3858 | J10: 2302449.2 | K10: 2 | L10: 485 | M10: 480 | N10: 177536.52 | O10: 454 | P10: 557335.73 | Q10: 2370.67 | R10: =G10*5% -> 96132.5 | S10: 2302449.2
B11: =TEXT(C11,"MMM-YYYY") -> Dec-2022 | C11: 44900 | D11: =$A$1-C11 -> 1212 | E11: 5621 | F11: 3465 | G11: 1688722 | H11: 3435 | I11: 3388 | J11: 1995587.2 | K11: 27 | L11: 8244.74 | M11: 529 | N11: 176526.66 | O11: 487 | P11: 483391.89 | Q11: 2870.43 | R11: =G11*5% -> 84436.1 | S11: 1995587.2
B12: =TEXT(C12,"MMM-YYYY") -> Dec-2022 | C12: 44901 | D12: =$A$1-C12 -> 1211 | E12: 4620 | F12: 3131 | G12: 1533780 | H12: 3115 | I12: 3082 | J12: 1845323.1 | K12: 18 | L12: 4952.69 | M12: 371 | N12: 134641.87 | O12: 347 | P12: 446184.94 | Q12: 2038.93 | R12: =G12*5% -> 76689 | S12: 1845323.1
B13: =TEXT(C13,"MMM-YYYY") -> Dec-2022 | C13: 44902 | D13: =$A$1-C13 -> 1210 | E13: 5554 | F13: 3445 | G13: 1682131 | H13: 3420 | I13: 3376 | J13: 2048559.8 | K13: 18 | L13: 4921.5 | M13: 355 | N13: 128598.89 | O13: 332 | P13: 495027.65 | Q13: 2209.63 | R13: =G13*5% -> 84106.55 | S13: 2048559.8
B14: =TEXT(C14,"MMM-YYYY") -> Dec-2022 | C14: 44903 | D14: =$A$1-C14 -> 1209 | E14: 5409 | F14: 4382 | G14: 2151140 | H14: 4362 | I14: 4318 | J14: 2692329.6 | K14: 21 | L14: 5414.89 | M14: 326 | N14: 107890.24 | O14: 296 | P14: 649079.83 | Q14: 1661.96 | R14: =G14*5% -> 107557 | S14: 2692329.6
B15: =TEXT(C15,"MMM-YYYY") -> Dec-2022 | C15: 44904 | D15: =$A$1-C15 -> 1208 | E15: 6080 | F15: 5225 | G15: 2594676 | H15: 5206 | I15: 5191 | J15: 3254965.8 | K15: 26 | L15: 8980.54 | M15: 316 | N15: 124371.26 | O15: 295 | P15: 784661.05 | Q15: 2634.74 | R15: =G15*5% -> 129733.8 | S15: 3254965.8
B16: =TEXT(C16,"MMM-YYYY") -> Dec-2022 | C16: 44905 | D16: =$A$1-C16 -> 1207 | E16: 6996 | F16: 6002 | G16: 2983103 | H16: 5987 | I16: 5973 | J16: 3813772.1 | K16: 17 | L16: 6466.15 | M16: 241 | N16: 86302.16 | O16: 218 | P16: 916971.31 | Q16: 1060.56 | R16: =G16*5% -> 149155.15 | S16: 3813772.1
B17: =TEXT(C17,"MMM-YYYY") -> Dec-2022 | C17: 44906 | D17: =$A$1-C17 -> 1206 | E17: 8052 | F17: 7138 | G17: 3550350 | H17: 7120 | I17: 7107 | J17: 4577054 | K17: 23 | L17: 8135.32 | M17: 186 | N17: 73066.31 | O17: 177 | P17: 1099770.3 | Q17: 1342.92 | R17: =G17*5% -> 177517.5 | S17: 4577054
B18: =TEXT(C18,"MMM-YYYY") -> Dec-2022 | C18: 44907 | D18: =$A$1-C18 -> 1205 | E18: 8533 | F18: 7388 | G18: 3672784 | H18: 7374 | I18: 7358 | J18: 4740705.1 | K18: 16 | L18: 5812.66 | M18: 177 | N18: 70020.65 | O18: 171 | P18: 1137941.8 | Q18: 860.71 | R18: =G18*5% -> 183639.2 | S18: 4740705.1
B19: =TEXT(C19,"MMM-YYYY") -> Dec-2022 | C19: 44908 | D19: =$A$1-C19 -> 1204 | E19: 8054 | F19: 6799 | G19: 3386535 | H19: 6788 | I19: 6779 | J19: 4341979.4 | K19: 17 | L19: 4124.81 | M19: 246 | N19: 87433.56 | O19: 225 | P19: 1042877.9 | Q19: 2364.59 | R19: =G19*5% -> 169326.75 | S19: 4341979.4
B20: =TEXT(C20,"MMM-YYYY") -> Dec-2022 | C20: 44909 | D20: =$A$1-C20 -> 1203 | E20: 10217 | F20: 8280 | G20: 4130675 | H20: 8271 | I20: 8268 | J20: 5315911.8 | K20: 14 | L20: 5302.88 | M20: 225 | N20: 90513.6 | O20: 215 | P20: 1275750.4 | Q20: 2523.02 | R20: =G20*5% -> 206533.75 | S20: 5315911.8
... B31: =TEXT(C31,"MMM-YYYY") -> Dec-2022 | C31: 44920 | D31: =$A$1-C31 -> 1192 | E31: 66 | F31: 142 | G31: 70550 | H31: 141 | I31: 141 | J31: 62127.3 | K31: 4 | L31: 1520.22 | M31: 66 | N31: 24135.6 | O31: 61 | P31: 15712.9 | Q31: 1082.06 | R31: =G31*5% -> 3527.5 | S31: 62127.3
B32: =TEXT(C32,"MMM-YYYY") -> Dec-2022 | C32: 44921 | D32: =$A$1-C32 -> 1191 | E32: 67 | F32: 160 | G32: 77835 | H32: 158 | I32: 156 | J32: 70736.8 | M32: 58 | N32: 24581.61 | O32: 54 | P32: 17483.41 | Q32: 730.58 | R32: =G32*5% -> 3891.75 | S32: 70736.8
B33: =TEXT(C33,"MMM-YYYY") -> Dec-2022 | C33: 44922 | D33: =$A$1-C33 -> 1190 | E33: 86 | F33: 185 | G33: 88400 | H33: 182 | I33: 178 | J33: 78588.03 | K33: 2 | L33: 880.11 | M33: 79 | N33: 29502.14 | O33: 69 | P33: 19690.17 | Q33: 1119.42 | R33: =G33*5% -> 4420 | S33: 78588.03
B34: =TEXT(C34,"MMM-YYYY") -> Dec-2022 | C34: 44923 | D34: =$A$1-C34 -> 1189 | E34: 76 | F34: 197 | G34: 94789 | H34: 197 | I34: 191 | J34: 75247.77 | K34: 3 | L34: 975.11 | M34: 95 | N34: 38110.62 | O34: 91 | P34: 18569.39 | Q34: 769.49 | R34: =G34*5% -> 4739.45 | S34: 75247.77
B35: =TEXT(C35,"MMM-YYYY") -> Dec-2022 | C35: 44924 | D35: =$A$1-C35 -> 1188 | E35: 84 | F35: 171 | G35: 83830 | H35: 171 | I35: 168 | J35: 78642.64 | K35: 4 | L35: 1450.11 | M35: 61 | N35: 24405.71 | O35: 55 | P35: 19218.35 | Q35: 667.54 | R35: =G35*5% -> 4191.5 | S35: 78642.64
B36: =TEXT(C36,"MMM-YYYY") -> Dec-2022 | C36: 44925 | D36: =$A$1-C36 -> 1187 | E36: 76 | F36: 183 | G36: 86625 | H36: 179 | I36: 173 | J36: 77756.07 | K36: 4 | L36: 1825.22 | M36: 66 | N36: 28165.93 | O36: 66 | P36: 19297 | Q36: 943.7 | R36: =G36*5% -> 4331.25 | S36: 77756.07
B37: =TEXT(C37,"MMM-YYYY") -> Dec-2022 | C37: 44926 | D37: =$A$1-C37 -> 1186 | E37: 72 | F37: 191 | G37: 90475 | H37: 188 | I37: 183 | J37: 69604.1 | K37: 10 | L37: 2512.22 | M37: 96 | N37: 38270.79 | O37: 85 | P37: 17399.89 | Q37: 965.36 | R37: =G37*5% -> 4523.75 | S37: 69604.1
B38: =TEXT(C38,"MMM-YYYY") -> Jan-2023 | C38: 44927 | D38: =$A$1-C38 -> 1185 | E38: 53 | F38: 99 | G38: 48997 | H38: 99 | I38: 97 | J38: 36277.04 | K38: 3 | L38: 1015.13 | M38: 50 | N38: 21706.47 | O38: 46 | P38: 8986.51 | Q38: 428.5 | R38: =G38*5% -> 2449.85 | S38: 36277.04
B39: =TEXT(C39,"MMM-YYYY") -> Jan-2023 | C39: 44928 | D39: =$A$1-C39 -> 1184 | E39: 32 | F39: 131 | G39: 63008 | H39: 130 | I39: 126 | J39: 49668.33 | M39: 59 | N39: 25866.39 | O39: 57 | P39: 12526.72 | Q39: 840.05 | R39: =G39*5% -> 3150.4 | S39: 49668.33
B40: =TEXT(C40,"MMM-YYYY") -> Jan-2023 | C40: 44929 | D40: =$A$1-C40 -> 1183 | E40: 65 | F40: 176 | G40: 83950 | H40: 173 | I40: 170 | J40: 70302.3 | M40: 69 | N40: 31089.62 | O40: 66 | P40: 17441.92 | Q40: 863.5 | R40: =G40*5% -> 4197.5 | S40: 70302.3
B41: =TEXT(C41,"MMM-YYYY") -> Jan-2023 | C41: 44930 | D41: =$A$1-C41 -> 1182 | E41: 78 | F41: 168 | G41: 80569 | H41: 167 | I41: 164 | J41: 74459.6 | M41: 60 | N41: 24062.13 | O41: 56 | P41: 17952.73 | Q41: 411.29 | R41: =G41*5% -> 4028.45 | S41: 74459.6
B42: =TEXT(C42,"MMM-YYYY") -> Jan-2023 | C42: 44931 | D42: =$A$1-C42 -> 1181 | E42: 63 | F42: 173 | G42: 82449 | H42: 170 | I42: 165 | J42: 61189.62 | M42: 93 | N42: 36358.71 | O42: 84 | P42: 15099.33 | Q42: 664.72 | R42: =G42*5% -> 4122.45 | S42: 61189.62
B43: =TEXT(C43,"MMM-YYYY") -> Jan-2023 | C43: 44932 | D43: =$A$1-C43 -> 1180 | E43: 55 | F43: 165 | G43: 81400 | H43: 164 | I43: 161 | J43: 62076.88 | K43: 2 | L43: 970.11 | M43: 85 | N43: 34712.68 | O43: 83 | P43: 15389.56 | Q43: 769.99 | R43: =G43*5% -> 4070 | S43: 62076.88
B44: =TEXT(C44,"MMM-YYYY") -> Jan-2023 | C44: 44933 | D44: =$A$1-C44 -> 1179 | E44: 52 | F44: 125 | G44: 61419 | H44: 125 | I44: 123 | J44: 50475.35 | K44: 1 | L44: 450 | M44: 55 | N44: 23475.22 | O44: 54 | P44: 12531.57 | Q44: 658 | R44: =G44*5% -> 3070.95 | S44: 50475.35
B45: =TEXT(C45,"MMM-YYYY") -> Jan-2023 | C45: 44934 | D45: =$A$1-C45 -> 1178 | E45: 41 | F45: 103 | G45: 47599 | H45: 102 | I45: 96 | J45: 40636.53 | K45: 1 | L45: 500.11 | M45: 44 | N45: 16816.53 | O45: 41 | P45: 9854.06 | Q45: 302.97 | R45: =G45*5% -> 2379.95 | S45: 40636.53
B46: =TEXT(C46,"MMM-YYYY") -> Jan-2023 | C46: 44935 | D46: =$A$1-C46 -> 1177 | E46: 55 | F46: 148 | G46: 71917 | H46: 146 | I46: 143 | J46: 61162.7 | K46: 4 | L46: 1375.11 | M46: 67 | N46: 25740.63 | O46: 63 | P46: 14986.33 | Q46: 654.03 | R46: =G46*5% -> 3595.85 | S46: 61162.7
B47: =TEXT(C47,"MMM-YYYY") -> Jan-2023 | C47: 44936 | D47: =$A$1-C47 -> 1176 | E47: 55 | F47: 137 | G47: 65274.5 | H47: 137 | I47: 133 | J47: 51472.38 | K47: 2 | L47: 340.55 | M47: 61 | N47: 26393.56 | O47: 61 | P47: 12591.44 | Q47: 481.82 | R47: =G47*5% -> 3263.725 | S47: 51472.38
B48: =TEXT(C48,"MMM-YYYY") -> Jan-2023 | C48: 44937 | D48: =$A$1-C48 -> 1175 | E48: 46 | F48: 123 | G48: 59369 | H48: 122 | I48: 119 | J48: 47333.28 | M48: 52 | N48: 23444.32 | O48: 49 | P48: 11408.6 | Q48: 288.94 | R48: =G48*5% -> 2968.45 | S48: 47333.28
B49: =TEXT(C49,"MMM-YYYY") -> Jan-2023 | C49: 44938 | D49: =$A$1-C49 -> 1174 | E49: 53 | F49: 149 | G49: 69404 | H49: 148 | I49: 143 | J49: 63649.82 | K49: 2 | L49: 970.11 | M49: 58 | N49: 21124.79 | O49: 56 | P49: 15370.61 | Q49: 429.53 | R49: =G49*5% -> 3470.2 | S49: 63649.82
B50: =TEXT(C50,"MMM-YYYY") -> Jan-2023 | C50: 44939 | D50: =$A$1-C50 -> 1173 | E50: 48 | F50: 165 | G50: 76000 | H50: 162 | I50: 153 | J50: 59472.42 | K50: 3 | L50: 950 | M50: 76 | N50: 31166.35 | O50: 73 | P50: 14638.77 | Q50: 726.92 | R50: =G50*5% -> 3800 | S50: 59472.42
...

Sheet Daily Summary(Airtel)
A1: 46112
